<?xml version="1.0" ?>
<testsuite errors="2" failures="0" name="MyTest-20180820114912" tests="3" time="7.617">
	<testcase classname="MyTest" name="testa" time="6.658"/>
	<testcase classname="MyTest" name="testb" time="0.749">
		<error message="3 != 2" type="AssertionError">
<![CDATA[Traceback (most recent call last):
  File "c:\Users\Hu\Documents\Study\unittest1.py", line 12, in testb
    self.assertEqual(3, 2)  #测试用例断言，比较预期结果与实际结果，这里3==1，显然结果是Fail
AssertionError: 3 != 2
]]>		</error>
	</testcase>
	<testcase classname="MyTest" name="testhaha" time="0.210">
		<error message="2 != 1" type="AssertionError">
<![CDATA[Traceback (most recent call last):
  File "c:\Users\Hu\Documents\Study\unittest1.py", line 9, in testhaha
    self.assertEqual(2, 1)  #测试用例断言，比较预期结果与实际结果，这里2==1，显然结果是Fail
AssertionError: 2 != 1
]]>		</error>
	</testcase>
	<system-out>
<![CDATA[]]>	</system-out>
	<system-err>
<![CDATA[]]>	</system-err>
</testsuite>
